[2024-12-02T07:04:30.906+0000] {local_task_job_runner.py:123} INFO - ::group::Pre task execution logs
[2024-12-02T07:04:30.912+0000] {taskinstance.py:2613} INFO - Dependencies all met for dep_context=non-requeueable deps ti=<TaskInstance: youtube_etl_dag.extract_data_from_youtube_api manual__2024-12-02T07:04:25.021858+00:00 [queued]>
[2024-12-02T07:04:30.915+0000] {taskinstance.py:2613} INFO - Dependencies all met for dep_context=requeueable deps ti=<TaskInstance: youtube_etl_dag.extract_data_from_youtube_api manual__2024-12-02T07:04:25.021858+00:00 [queued]>
[2024-12-02T07:04:30.915+0000] {taskinstance.py:2866} INFO - Starting attempt 1 of 2
[2024-12-02T07:04:30.926+0000] {taskinstance.py:2889} INFO - Executing <Task(PythonOperator): extract_data_from_youtube_api> on 2024-12-02 07:04:25.021858+00:00
[2024-12-02T07:04:30.935+0000] {standard_task_runner.py:72} INFO - Started process 116 to run task
[2024-12-02T07:04:30.937+0000] {standard_task_runner.py:104} INFO - Running: ['airflow', 'tasks', 'run', 'youtube_etl_dag', 'extract_data_from_youtube_api', 'manual__2024-12-02T07:04:25.021858+00:00', '--job-id', '4', '--raw', '--subdir', 'DAGS_FOLDER/youtube_etl_dag.py', '--cfg-path', '/tmp/tmp5izglpfh']
[2024-12-02T07:04:30.939+0000] {standard_task_runner.py:105} INFO - Job 4: Subtask extract_data_from_youtube_api
[2024-12-02T07:04:30.968+0000] {task_command.py:467} INFO - Running <TaskInstance: youtube_etl_dag.extract_data_from_youtube_api manual__2024-12-02T07:04:25.021858+00:00 [running]> on host 2d6f41b077e8
[2024-12-02T07:04:31.003+0000] {taskinstance.py:3132} INFO - Exporting env vars: AIRFLOW_CTX_DAG_OWNER='airflow' AIRFLOW_CTX_DAG_ID='youtube_etl_dag' AIRFLOW_CTX_TASK_ID='extract_data_from_youtube_api' AIRFLOW_CTX_EXECUTION_DATE='2024-12-02T07:04:25.021858+00:00' AIRFLOW_CTX_TRY_NUMBER='1' AIRFLOW_CTX_DAG_RUN_ID='manual__2024-12-02T07:04:25.021858+00:00'
[2024-12-02T07:04:31.003+0000] {taskinstance.py:731} INFO - ::endgroup::
[2024-12-02T07:04:31.011+0000] {__init__.py:49} INFO - file_cache is only supported with oauth2client<4.0.0
[2024-12-02T07:04:31.439+0000] {taskinstance.py:3311} ERROR - Task failed with exception
Traceback (most recent call last):
  File "/home/airflow/.local/lib/python3.12/site-packages/airflow/models/taskinstance.py", line 767, in _execute_task
    result = _execute_callable(context=context, **execute_callable_kwargs)
             ^^^^^^^^^^^^^^^^^^^^^^^^^^^^^^^^^^^^^^^^^^^^^^^^^^^^^^^^^^^^^
  File "/home/airflow/.local/lib/python3.12/site-packages/airflow/models/taskinstance.py", line 733, in _execute_callable
    return ExecutionCallableRunner(
           ^^^^^^^^^^^^^^^^^^^^^^^^
  File "/home/airflow/.local/lib/python3.12/site-packages/airflow/utils/operator_helpers.py", line 252, in run
    return self.func(*args, **kwargs)
           ^^^^^^^^^^^^^^^^^^^^^^^^^^
  File "/home/airflow/.local/lib/python3.12/site-packages/airflow/models/baseoperator.py", line 417, in wrapper
    return func(self, *args, **kwargs)
           ^^^^^^^^^^^^^^^^^^^^^^^^^^^
  File "/home/airflow/.local/lib/python3.12/site-packages/airflow/operators/python.py", line 238, in execute
    return_value = self.execute_callable()
                   ^^^^^^^^^^^^^^^^^^^^^^^
  File "/home/airflow/.local/lib/python3.12/site-packages/airflow/operators/python.py", line 256, in execute_callable
    return runner.run(*self.op_args, **self.op_kwargs)
           ^^^^^^^^^^^^^^^^^^^^^^^^^^^^^^^^^^^^^^^^^^^
  File "/home/airflow/.local/lib/python3.12/site-packages/airflow/utils/operator_helpers.py", line 252, in run
    return self.func(*args, **kwargs)
           ^^^^^^^^^^^^^^^^^^^^^^^^^^
  File "/opt/airflow/dags/youtube_etl_dag.py", line 45, in extract_data
    df_trending_videos = fetch_data(api_key, region_codes, category_ids)
                         ^^^^^^^^^^^^^^^^^^^^^^^^^^^^^^^^^^^^^^^^^^^^^^^
  File "/opt/airflow/dags/youtube_etl_dag.py", line 75, in fetch_data
    response = request.execute()
               ^^^^^^^^^^^^^^^^^
  File "/home/airflow/.local/lib/python3.12/site-packages/googleapiclient/_helpers.py", line 130, in positional_wrapper
    return wrapped(*args, **kwargs)
           ^^^^^^^^^^^^^^^^^^^^^^^^
  File "/home/airflow/.local/lib/python3.12/site-packages/googleapiclient/http.py", line 938, in execute
    raise HttpError(resp, content, uri=self.uri)
googleapiclient.errors.HttpError: <HttpError 400 when requesting https://youtube.googleapis.com/youtube/v3/videos?part=snippet%2CcontentDetails%2Cstatistics&chart=mostPopular&regionCode=US&videoCategoryId=1&maxResults=50&key=%27AIzaSyC9e_LXg_F5v8rdjgg2qj3cWDjrQ8ws2Ow%27&alt=json returned "API key not valid. Please pass a valid API key.". Details: "[{'message': 'API key not valid. Please pass a valid API key.', 'domain': 'global', 'reason': 'badRequest'}]">
[2024-12-02T07:04:31.456+0000] {taskinstance.py:1225} INFO - Marking task as UP_FOR_RETRY. dag_id=youtube_etl_dag, task_id=extract_data_from_youtube_api, run_id=manual__2024-12-02T07:04:25.021858+00:00, execution_date=20241202T070425, start_date=20241202T070430, end_date=20241202T070431
[2024-12-02T07:04:31.481+0000] {taskinstance.py:340} INFO - ::group::Post task execution logs
[2024-12-02T07:04:31.482+0000] {standard_task_runner.py:124} ERROR - Failed to execute job 4 for task extract_data_from_youtube_api (<HttpError 400 when requesting https://youtube.googleapis.com/youtube/v3/videos?part=snippet%2CcontentDetails%2Cstatistics&chart=mostPopular&regionCode=US&videoCategoryId=1&maxResults=50&key=%27AIzaSyC9e_LXg_F5v8rdjgg2qj3cWDjrQ8ws2Ow%27&alt=json returned "API key not valid. Please pass a valid API key.". Details: "[{'message': 'API key not valid. Please pass a valid API key.', 'domain': 'global', 'reason': 'badRequest'}]">; 116)
Traceback (most recent call last):
  File "/home/airflow/.local/lib/python3.12/site-packages/airflow/task/task_runner/standard_task_runner.py", line 117, in _start_by_fork
    ret = args.func(args, dag=self.dag)
          ^^^^^^^^^^^^^^^^^^^^^^^^^^^^^
  File "/home/airflow/.local/lib/python3.12/site-packages/airflow/cli/cli_config.py", line 49, in command
    return func(*args, **kwargs)
           ^^^^^^^^^^^^^^^^^^^^^
  File "/home/airflow/.local/lib/python3.12/site-packages/airflow/utils/cli.py", line 116, in wrapper
    return f(*args, **kwargs)
           ^^^^^^^^^^^^^^^^^^
  File "/home/airflow/.local/lib/python3.12/site-packages/airflow/cli/commands/task_command.py", line 483, in task_run
    task_return_code = _run_task_by_selected_method(args, _dag, ti)
                       ^^^^^^^^^^^^^^^^^^^^^^^^^^^^^^^^^^^^^^^^^^^^
  File "/home/airflow/.local/lib/python3.12/site-packages/airflow/cli/commands/task_command.py", line 256, in _run_task_by_selected_method
    return _run_raw_task(args, ti)
           ^^^^^^^^^^^^^^^^^^^^^^^
  File "/home/airflow/.local/lib/python3.12/site-packages/airflow/cli/commands/task_command.py", line 341, in _run_raw_task
    return ti._run_raw_task(
           ^^^^^^^^^^^^^^^^^
  File "/home/airflow/.local/lib/python3.12/site-packages/airflow/utils/session.py", line 97, in wrapper
    return func(*args, session=session, **kwargs)
           ^^^^^^^^^^^^^^^^^^^^^^^^^^^^^^^^^^^^^^
  File "/home/airflow/.local/lib/python3.12/site-packages/airflow/models/taskinstance.py", line 3005, in _run_raw_task
    return _run_raw_task(
           ^^^^^^^^^^^^^^
  File "/home/airflow/.local/lib/python3.12/site-packages/airflow/models/taskinstance.py", line 273, in _run_raw_task
    TaskInstance._execute_task_with_callbacks(
  File "/home/airflow/.local/lib/python3.12/site-packages/airflow/models/taskinstance.py", line 3159, in _execute_task_with_callbacks
    result = self._execute_task(context, task_orig)
             ^^^^^^^^^^^^^^^^^^^^^^^^^^^^^^^^^^^^^^
  File "/home/airflow/.local/lib/python3.12/site-packages/airflow/models/taskinstance.py", line 3183, in _execute_task
    return _execute_task(self, context, task_orig)
           ^^^^^^^^^^^^^^^^^^^^^^^^^^^^^^^^^^^^^^^
  File "/home/airflow/.local/lib/python3.12/site-packages/airflow/models/taskinstance.py", line 767, in _execute_task
    result = _execute_callable(context=context, **execute_callable_kwargs)
             ^^^^^^^^^^^^^^^^^^^^^^^^^^^^^^^^^^^^^^^^^^^^^^^^^^^^^^^^^^^^^
  File "/home/airflow/.local/lib/python3.12/site-packages/airflow/models/taskinstance.py", line 733, in _execute_callable
    return ExecutionCallableRunner(
           ^^^^^^^^^^^^^^^^^^^^^^^^
  File "/home/airflow/.local/lib/python3.12/site-packages/airflow/utils/operator_helpers.py", line 252, in run
    return self.func(*args, **kwargs)
           ^^^^^^^^^^^^^^^^^^^^^^^^^^
  File "/home/airflow/.local/lib/python3.12/site-packages/airflow/models/baseoperator.py", line 417, in wrapper
    return func(self, *args, **kwargs)
           ^^^^^^^^^^^^^^^^^^^^^^^^^^^
  File "/home/airflow/.local/lib/python3.12/site-packages/airflow/operators/python.py", line 238, in execute
    return_value = self.execute_callable()
                   ^^^^^^^^^^^^^^^^^^^^^^^
  File "/home/airflow/.local/lib/python3.12/site-packages/airflow/operators/python.py", line 256, in execute_callable
    return runner.run(*self.op_args, **self.op_kwargs)
           ^^^^^^^^^^^^^^^^^^^^^^^^^^^^^^^^^^^^^^^^^^^
  File "/home/airflow/.local/lib/python3.12/site-packages/airflow/utils/operator_helpers.py", line 252, in run
    return self.func(*args, **kwargs)
           ^^^^^^^^^^^^^^^^^^^^^^^^^^
  File "/opt/airflow/dags/youtube_etl_dag.py", line 45, in extract_data
    df_trending_videos = fetch_data(api_key, region_codes, category_ids)
                         ^^^^^^^^^^^^^^^^^^^^^^^^^^^^^^^^^^^^^^^^^^^^^^^
  File "/opt/airflow/dags/youtube_etl_dag.py", line 75, in fetch_data
    response = request.execute()
               ^^^^^^^^^^^^^^^^^
  File "/home/airflow/.local/lib/python3.12/site-packages/googleapiclient/_helpers.py", line 130, in positional_wrapper
    return wrapped(*args, **kwargs)
           ^^^^^^^^^^^^^^^^^^^^^^^^
  File "/home/airflow/.local/lib/python3.12/site-packages/googleapiclient/http.py", line 938, in execute
    raise HttpError(resp, content, uri=self.uri)
googleapiclient.errors.HttpError: <HttpError 400 when requesting https://youtube.googleapis.com/youtube/v3/videos?part=snippet%2CcontentDetails%2Cstatistics&chart=mostPopular&regionCode=US&videoCategoryId=1&maxResults=50&key=%27AIzaSyC9e_LXg_F5v8rdjgg2qj3cWDjrQ8ws2Ow%27&alt=json returned "API key not valid. Please pass a valid API key.". Details: "[{'message': 'API key not valid. Please pass a valid API key.', 'domain': 'global', 'reason': 'badRequest'}]">
[2024-12-02T07:04:31.529+0000] {local_task_job_runner.py:266} INFO - Task exited with return code 1
[2024-12-02T07:04:31.545+0000] {taskinstance.py:3895} INFO - 0 downstream tasks scheduled from follow-on schedule check
[2024-12-02T07:04:31.546+0000] {local_task_job_runner.py:245} INFO - ::endgroup::
